Workbook

Sheet Category Mapping
A1: Raw Value (exact) | B1: Standardized Category
A2: ABAYA | B2: Abaya
A3: prayer set | B3: Prayer Set
A4: Hijabs | B4: Hijab
A5: Accessories | B5: Accessories
A6: Abaya | B6: Abaya
A7: Hijab | B7: Hijab
A8: Prayer Set | B8: Prayer Set
A9: Accesories | B9: Accessories
A10: PrayerSet | B10: Prayer Set
A11: Abaya | B11: Abaya
A12: Hijab | B12: Hijab
... A23: New Arrival | B23: NOT MAPPED - INVALID

Sheet Size Mapping
A1: Raw Value (exact) | B1: Standardized Size
A2: M | B2: M
A3: All Size | B3: All Size
A4: All size | B4: All Size
A5: Free Size | B5: All Size
A6: M | B6: M
A7: m | B7: M
A8: AllSize | B8: All Size
A9: ALLSIZE | B9: All Size
A10: XL | B10: XL
A11: L | B11: L
A12: all size | B12: All Size
... A19: XL | B19: XL

Sheet Cleaned Catalog
A1: Raw Row # | B1: SKU | C1: Duplicate SKU Flag | D1: Product Name | E1: Category (Raw) | F1: Category (Standardized) | G1: Color (Raw) | H1: Color (Standardized) | I1: Size (Raw) | J1: Size (Standardized) | K1: Price | L1: Price Check | M1: Stock Quantity | N1: Stock Check | O1: Issue Count | P1: Issue / Reason | Q1: Marketplace Status
A2: 5 | B2: AMC-127 | C2: =IF(B2="","",IF(COUNTIF($B$2:$B$50,B2)>1,"Duplicate SKU","")) | D2: Abaya Nida Basic | E2: ABAYA | F2: =IFERROR(VLOOKUP(E2,'Category Mapping'!$A$2:$B$23,2,FALSE()),"NOT MAPPED") -> Abaya | G2: NAVY | H2: =IF(TRIM(G2)="","",PROPER(TRIM(G2))) -> Navy | I2: M | J2: =IFERROR(VLOOKUP(I2,'Size Mapping'!$A$2:$B$19,2,FALSE()),"NOT MAPPED") -> M | K2: 38 | L2: =IF(ISBLANK(K2),"Missing",IF(NOT(ISNUMBER(K2)),"Non-numeric",IF(K2<=0,"Invalid (<=0)","OK"))) -> OK | M2: 8 | N2: =IF(ISBLANK(M2),"Missing",IF(NOT(ISNUMBER(M2)),"Non-numeric",IF(M2<0,"Invalid (negative)","OK"))) -> OK | O2: =IF(B2="",1,0)+IF(C2="Duplicate SKU",1,0)+IF(D2="",1,0)+IF(LEFT(F2,10)="NOT MAPPED",1,0)+IF(LEFT(J2,10)="NOT MAPPED",1,0)+IF(L2="OK",0,1)+IF(N2="OK",0,1) -> 0 | P2: =IF(RIGHT(IF(B2="","Missing SKU; ","")&IF(C2="Duplicate SKU","Duplicate SKU; ","")&IF(D2="","Missing Product Name; ","")&IF(LEFT(F2,10)="NOT MAPPED","Invalid Category ("&E2&"); ","")&IF(LEFT(J2,10)="NOT MAPPED","Invalid Size ("&I2&"); ","")&IF(L2<>"OK","Invalid Price ("&L2&"); ","")&IF(N2<>"OK","Invalid Stock ("&N2&"); ",""),2)="; ",LEFT(IF(B2="","Missing SKU; ","")&IF(C2="Duplicate SKU","Duplicate SKU; ","")&IF(D2="","Missing Product Name; ","")&IF(LEFT(F2,10)="NOT MAPPED","Invalid Category ("&E2&"); ","")&IF(LEFT(J2,10)="NOT MAPPED","Invalid Size ("&I2&"); ","")&IF(L2<>"OK","Invalid Price ("&L2&"); ","")&IF(N2<>"OK","Invalid Stock ("&N2&"); ",""),LEN(IF(B2="","Missing SKU; ","")&IF(C2="Duplicate SKU","Duplicate SKU; ","")&IF(D2="","Missing Product Name; ","")&IF(LEFT(F2,10)="NOT MAPPED","Invalid Category ("&E2&"); ","")&IF(LEFT(J2,10)="NOT MAPPED","Invalid Size ("&I2&"); ","")&IF(L2<>"OK","Invalid Price ("&L2&"); ","")&IF(N2<>"OK","Invalid Stock ("&N2&"); ",""))-2),IF(B2="","Missing SKU; ","")&IF(C2="Duplicate SKU","Duplicate SKU; ","")&IF(D2="","Missing Product Name; ","")&IF(LEFT(F2,10)="NOT MAPPED","Invalid Category ("&E2&"); ","")&IF(LEFT(J2,10)="NOT MAPPED","Invalid Size ("&I2&"); ","")&IF(L2<>"OK","Invalid Price ("&L2&"); ","")&IF(N2<>"OK","Invalid Stock ("&N2&"); ","")) | Q2: =IF(O2=0,"Ready to List",IF(O2=1,"Needs Review","Incomplete")) -> Ready to List
A3: 6 | B3: AMC-136 | C3: =IF(B3="","",IF(COUNTIF($B$2:$B$50,B3)>1,"Duplicate SKU","")) | D3: Sajadah Travel Roll | E3: prayer set | F3: =IFERROR(VLOOKUP(E3,'Category Mapping'!$A$2:$B$23,2,FALSE()),"NOT MAPPED") -> Prayer Set | G3: navy | H3: =IF(TRIM(G3)="","",PROPER(TRIM(G3))) -> Navy | I3: All Size | J3: =IFERROR(VLOOKUP(I3,'Size Mapping'!$A$2:$B$19,2,FALSE()),"NOT MAPPED") -> All Size | K3: 9 | L3: =IF(ISBLANK(K3),"Missing",IF(NOT(ISNUMBER(K3)),"Non-numeric",IF(K3<=0,"Invalid (<=0)","OK"))) -> OK | N3: =IF(ISBLANK(M3),"Missing",IF(NOT(ISNUMBER(M3)),"Non-numeric",IF(M3<0,"Invalid (negative)","OK"))) -> Missing | O3: =IF(B3="",1,0)+IF(C3="Duplicate SKU",1,0)+IF(D3="",1,0)+IF(LEFT(F3,10)="NOT MAPPED",1,0)+IF(LEFT(J3,10)="NOT MAPPED",1,0)+IF(L3="OK",0,1)+IF(N3="OK",0,1) -> 1 | P3: =IF(RIGHT(IF(B3="","Missing SKU; ","")&IF(C3="Duplicate SKU","Duplicate SKU; ","")&IF(D3="","Missing Product Name; ","")&IF(LEFT(F3,10)="NOT MAPPED","Invalid Category ("&E3&"); ","")&IF(LEFT(J3,10)="NOT MAPPED","Invalid Size ("&I3&"); ","")&IF(L3<>"OK","Invalid Price ("&L3&"); ","")&IF(N3<>"OK","Invalid Stock ("&N3&"); ",""),2)="; ",LEFT(IF(B3="","Missing SKU; ","")&IF(C3="Duplicate SKU","Duplicate SKU; ","")&IF(D3="","Missing Product Name; ","")&IF(LEFT(F3,10)="NOT MAPPED","Invalid Category ("&E3&"); ","")&IF(LEFT(J3,10)="NOT MAPPED","Invalid Size ("&I3&"); ","")&IF(L3<>"OK","Invalid Price ("&L3&"); ","")&IF(N3<>"OK","Invalid Stock ("&N3&"); ",""),LEN(IF(B3="","Missing SKU; ","")&IF(C3="Duplicate SKU","Duplicate SKU; ","")&IF(D3="","Missing Product Name; ","")&IF(LEFT(F3,10)="NOT MAPPED","Invalid Category ("&E3&"); ","")&IF(LEFT(J3,10)="NOT MAPPED","Invalid Size ("&I3&"); ","")&IF(L3<>"OK","Invalid Price ("&L3&"); ","")&IF(N3<>"OK","Invalid Stock ("&N3&"); ",""))-2),IF(B3="","Missing SKU; ","")&IF(C3="Duplicate SKU","Duplicate SKU; ","")&IF(D3="","Missing Product Name; ","")&IF(LEFT(F3,10)="NOT MAPPED","Invalid Category ("&E3&"); ","")&IF(LEFT(J3,10)="NOT MAPPED","Invalid Size ("&I3&"); ","")&IF(L3<>"OK","Invalid Price ("&L3&"); ","")&IF(N3<>"OK","Invalid Stock ("&N3&"); ","")) -> Invalid Stock (Missing) | Q3: =IF(O3=0,"Ready to List",IF(O3=1,"Needs Review","Incomplete")) -> Needs Review
A4: 7 | B4: AMC-122 | C4: =IF(B4="","",IF(COUNTIF($B$2:$B$50,B4)>1,"Duplicate SKU","")) -> Duplicate SKU | D4: Pashmina Diamond Italiano | E4: Hijabs | F4: =IFERROR(VLOOKUP(E4,'Category Mapping'!$A$2:$B$23,2,FALSE()),"NOT MAPPED") -> Hijab | G4: ivory | H4: =IF(TRIM(G4)="","",PROPER(TRIM(G4))) -> Ivory | I4: All size | J4: =IFERROR(VLOOKUP(I4,'Size Mapping'!$A$2:$B$19,2,FALSE()),"NOT MAPPED") -> All Size | K4: 12.5 | L4: =IF(ISBLANK(K4),"Missing",IF(NOT(ISNUMBER(K4)),"Non-numeric",IF(K4<=0,"Invalid (<=0)","OK"))) -> OK | M4: 20 | N4: =IF(ISBLANK(M4),"Missing",IF(NOT(ISNUMBER(M4)),"Non-numeric",IF(M4<0,"Invalid (negative)","OK"))) -> OK | O4: =IF(B4="",1,0)+IF(C4="Duplicate SKU",1,0)+IF(D4="",1,0)+IF(LEFT(F4,10)="NOT MAPPED",1,0)+IF(LEFT(J4,10)="NOT MAPPED",1,0)+IF(L4="OK",0,1)+IF(N4="OK",0,1) -> 1 | P4: =IF(RIGHT(IF(B4="","Missing SKU; ","")&IF(C4="Duplicate SKU","Duplicate SKU; ","")&IF(D4="","Missing Product Name; ","")&IF(LEFT(F4,10)="NOT MAPPED","Invalid Category ("&E4&"); ","")&IF(LEFT(J4,10)="NOT MAPPED","Invalid Size ("&I4&"); ","")&IF(L4<>"OK","Invalid Price ("&L4&"); ","")&IF(N4<>"OK","Invalid Stock ("&N4&"); ",""),2)="; ",LEFT(IF(B4="","Missing SKU; ","")&IF(C4="Duplicate SKU","Duplicate SKU; ","")&IF(D4="","Missing Product Name; ","")&IF(LEFT(F4,10)="NOT MAPPED","Invalid Category ("&E4&"); ","")&IF(LEFT(J4,10)="NOT MAPPED","Invalid Size ("&I4&"); ","")&IF(L4<>"OK","Invalid Price ("&L4&"); ","")&IF(N4<>"OK","Invalid Stock ("&N4&"); ",""),LEN(IF(B4="","Missing SKU; ","")&IF(C4="Duplicate SKU","Duplicate SKU; ","")&IF(D4="","Missing Product Name; ","")&IF(LEFT(F4,10)="NOT MAPPED","Invalid Category ("&E4&"); ","")&IF(LEFT(J4,10)="NOT MAPPED","Invalid Size ("&I4&"); ","")&IF(L4<>"OK","Invalid Price ("&L4&"); ","")&IF(N4<>"OK","Invalid Stock ("&N4&"); ",""))-2),IF(B4="","Missing SKU; ","")&IF(C4="Duplicate SKU","Duplicate SKU; ","")&IF(D4="","Missing Product Name; ","")&IF(LEFT(F4,10)="NOT MAPPED","Invalid Category ("&E4&"); ","")&IF(LEFT(J4,10)="NOT MAPPED","Invalid Size ("&I4&"); ","")&IF(L4<>"OK","Invalid Price ("&L4&"); ","")&IF(N4<>"OK","Invalid Stock ("&N4&"); ","")) -> Duplicate SKU | Q4: =IF(O4=0,"Ready to List",IF(O4=1,"Needs Review","Incomplete")) -> Needs Review
A5: 8 | B5: AMC-145 | C5: =IF(B5="","",IF(COUNTIF($B$2:$B$50,B5)>1,"Duplicate SKU","")) | D5: Manset Baju Kaos | E5: Accessories | F5: =IFERROR(VLOOKUP(E5,'Category Mapping'!$A$2:$B$23,2,FALSE()),"NOT MAPPED") -> Accessories | G5: Black | H5: =IF(TRIM(G5)="","",PROPER(TRIM(G5))) -> Black | I5: Free Size | J5: =IFERROR(VLOOKUP(I5,'Size Mapping'!$A$2:$B$19,2,FALSE()),"NOT MAPPED") -> All Size | K5: 5 | L5: =IF(ISBLANK(K5),"Missing",IF(NOT(ISNUMBER(K5)),"Non-numeric",IF(K5<=0,"Invalid (<=0)","OK"))) -> OK | M5: 31 | N5: =IF(ISBLANK(M5),"Missing",IF(NOT(ISNUMBER(M5)),"Non-numeric",IF(M5<0,"Invalid (negative)","OK"))) -> OK | O5: =IF(B5="",1,0)+IF(C5="Duplicate SKU",1,0)+IF(D5="",1,0)+IF(LEFT(F5,10)="NOT MAPPED",1,0)+IF(LEFT(J5,10)="NOT MAPPED",1,0)+IF(L5="OK",0,1)+IF(N5="OK",0,1) -> 0 | P5: =IF(RIGHT(IF(B5="","Missing SKU; ","")&IF(C5="Duplicate SKU","Duplicate SKU; ","")&IF(D5="","Missing Product Name; ","")&IF(LEFT(F5,10)="NOT MAPPED","Invalid Category ("&E5&"); ","")&IF(LEFT(J5,10)="NOT MAPPED","Invalid Size ("&I5&"); ","")&IF(L5<>"OK","Invalid Price ("&L5&"); ","")&IF(N5<>"OK","Invalid Stock ("&N5&"); ",""),2)="; ",LEFT(IF(B5="","Missing SKU; ","")&IF(C5="Duplicate SKU","Duplicate SKU; ","")&IF(D5="","Missing Product Name; ","")&IF(LEFT(F5,10)="NOT MAPPED","Invalid Category ("&E5&"); ","")&IF(LEFT(J5,10)="NOT MAPPED","Invalid Size ("&I5&"); ","")&IF(L5<>"OK","Invalid Price ("&L5&"); ","")&IF(N5<>"OK","Invalid Stock ("&N5&"); ",""),LEN(IF(B5="","Missing SKU; ","")&IF(C5="Duplicate SKU","Duplicate SKU; ","")&IF(D5="","Missing Product Name; ","")&IF(LEFT(F5,10)="NOT MAPPED","Invalid Category ("&E5&"); ","")&IF(LEFT(J5,10)="NOT MAPPED","Invalid Size ("&I5&"); ","")&IF(L5<>"OK","Invalid Price ("&L5&"); ","")&IF(N5<>"OK","Invalid Stock ("&N5&"); ",""))-2),IF(B5="","Missing SKU; ","")&IF(C5="Duplicate SKU","Duplicate SKU; ","")&IF(D5="","Missing Product Name; ","")&IF(LEFT(F5,10)="NOT MAPPED","Invalid Category ("&E5&"); ","")&IF(LEFT(J5,10)="NOT MAPPED","Invalid Size ("&I5&"); ","")&IF(L5<>"OK","Invalid Price ("&L5&"); ","")&IF(N5<>"OK","Invalid Stock ("&N5&"); ","")) | Q5: =IF(O5=0,"Ready to List",IF(O5=1,"Needs Review","Incomplete")) -> Ready to List
A6: 9 | B6: AMC-141 | C6: =IF(B6="","",IF(COUNTIF($B$2:$B$50,B6)>1,"Duplicate SKU","")) | D6: Pashmina Diamond Italiano | E6: Hijabs | F6: =IFERROR(VLOOKUP(E6,'Category Mapping'!$A$2:$B$23,2,FALSE()),"NOT MAPPED") -> Hijab | G6: sage green | H6: =IF(TRIM(G6)="","",PROPER(TRIM(G6))) -> Sage Green | I6: All size | J6: =IFERROR(VLOOKUP(I6,'Size Mapping'!$A$2:$B$19,2,FALSE()),"NOT MAPPED") -> All Size | K6: 12.5 | L6: =IF(ISBLANK(K6),"Missing",IF(NOT(ISNUMBER(K6)),"Non-numeric",IF(K6<=0,"Invalid (<=0)","OK"))) -> OK | M6: 24 | N6: =IF(ISBLANK(M6),"Missing",IF(NOT(ISNUMBER(M6)),"Non-numeric",IF(M6<0,"Invalid (negative)","OK"))) -> OK | O6: =IF(B6="",1,0)+IF(C6="Duplicate SKU",1,0)+IF(D6="",1,0)+IF(LEFT(F6,10)="NOT MAPPED",1,0)+IF(LEFT(J6,10)="NOT MAPPED",1,0)+IF(L6="OK",0,1)+IF(N6="OK",0,1) -> 0 | P6: =IF(RIGHT(IF(B6="","Missing SKU; ","")&IF(C6="Duplicate SKU","Duplicate SKU; ","")&IF(D6="","Missing Product Name; ","")&IF(LEFT(F6,10)="NOT MAPPED","Invalid Category ("&E6&"); ","")&IF(LEFT(J6,10)="NOT MAPPED","Invalid Size ("&I6&"); ","")&IF(L6<>"OK","Invalid Price ("&L6&"); ","")&IF(N6<>"OK","Invalid Stock ("&N6&"); ",""),2)="; ",LEFT(IF(B6="","Missing SKU; ","")&IF(C6="Duplicate SKU","Duplicate SKU; ","")&IF(D6="","Missing Product Name; ","")&IF(LEFT(F6,10)="NOT MAPPED","Invalid Category ("&E6&"); ","")&IF(LEFT(J6,10)="NOT MAPPED","Invalid Size ("&I6&"); ","")&IF(L6<>"OK","Invalid Price ("&L6&"); ","")&IF(N6<>"OK","Invalid Stock ("&N6&"); ",""),LEN(IF(B6="","Missing SKU; ","")&IF(C6="Duplicate SKU","Duplicate SKU; ","")&IF(D6="","Missing Product Name; ","")&IF(LEFT(F6,10)="NOT MAPPED","Invalid Category ("&E6&"); ","")&IF(LEFT(J6,10)="NOT MAPPED","Invalid Size ("&I6&"); ","")&IF(L6<>"OK","Invalid Price ("&L6&"); ","")&IF(N6<>"OK","Invalid Stock ("&N6&"); ",""))-2),IF(B6="","Missing SKU; ","")&IF(C6="Duplicate SKU","Duplicate SKU; ","")&IF(D6="","Missing Product Name; ","")&IF(LEFT(F6,10)="NOT MAPPED","Invalid Category ("&E6&"); ","")&IF(LEFT(J6,10)="NOT MAPPED","Invalid Size ("&I6&"); ","")&IF(L6<>"OK","Invalid Price ("&L6&"); ","")&IF(N6<>"OK","Invalid Stock ("&N6&"); ","")) | Q6: =IF(O6=0,"Ready to List",IF(O6=1,"Needs Review","Incomplete")) -> Ready to List
A7: 10 | B7: AMC-108 | C7: =IF(B7="","",IF(COUNTIF($B$2:$B$50,B7)>1,"Duplicate SKU","")) | D7: Khimar Jersey 2 Layer | E7: Abaya | F7: =IFERROR(VLOOKUP(E7,'Category Mapping'!$A$2:$B$23,2,FALSE()),"NOT MAPPED") -> Abaya | G7: Black | H7: =IF(TRIM(G7)="","",PROPER(TRIM(G7))) -> Black | I7: M | J7: =IFERROR(VLOOKUP(I7,'Size Mapping'!$A$2:$B$19,2,FALSE()),"NOT MAPPED") -> M | K7: 24 | L7: =IF(ISBLANK(K7),"Missing",IF(NOT(ISNUMBER(K7)),"Non-numeric",IF(K7<=0,"Invalid (<=0)","OK"))) -> OK | M7: 12 | N7: =IF(ISBLANK(M7),"Missing",IF(NOT(ISNUMBER(M7)),"Non-numeric",IF(M7<0,"Invalid (negative)","OK"))) -> OK | O7: =IF(B7="",1,0)+IF(C7="Duplicate SKU",1,0)+IF(D7="",1,0)+IF(LEFT(F7,10)="NOT MAPPED",1,0)+IF(LEFT(J7,10)="NOT MAPPED",1,0)+IF(L7="OK",0,1)+IF(N7="OK",0,1) -> 0 | P7: =IF(RIGHT(IF(B7="","Missing SKU; ","")&IF(C7="Duplicate SKU","Duplicate SKU; ","")&IF(D7="","Missing Product Name; ","")&IF(LEFT(F7,10)="NOT MAPPED","Invalid Category ("&E7&"); ","")&IF(LEFT(J7,10)="NOT MAPPED","Invalid Size ("&I7&"); ","")&IF(L7<>"OK","Invalid Price ("&L7&"); ","")&IF(N7<>"OK","Invalid Stock ("&N7&"); ",""),2)="; ",LEFT(IF(B7="","Missing SKU; ","")&IF(C7="Duplicate SKU","Duplicate SKU; ","")&IF(D7="","Missing Product Name; ","")&IF(LEFT(F7,10)="NOT MAPPED","Invalid Category ("&E7&"); ","")&IF(LEFT(J7,10)="NOT MAPPED","Invalid Size ("&I7&"); ","")&IF(L7<>"OK","Invalid Price ("&L7&"); ","")&IF(N7<>"OK","Invalid Stock ("&N7&"); ",""),LEN(IF(B7="","Missing SKU; ","")&IF(C7="Duplicate SKU","Duplicate SKU; ","")&IF(D7="","Missing Product Name; ","")&IF(LEFT(F7,10)="NOT MAPPED","Invalid Category ("&E7&"); ","")&IF(LEFT(J7,10)="NOT MAPPED","Invalid Size ("&I7&"); ","")&IF(L7<>"OK","Invalid Price ("&L7&"); ","")&IF(N7<>"OK","Invalid Stock ("&N7&"); ",""))-2),IF(B7="","Missing SKU; ","")&IF(C7="Duplicate SKU","Duplicate SKU; ","")&IF(D7="","Missing Product Name; ","")&IF(LEFT(F7,10)="NOT MAPPED","Invalid Category ("&E7&"); ","")&IF(LEFT(J7,10)="NOT MAPPED","Invalid Size ("&I7&"); ","")&IF(L7<>"OK","Invalid Price ("&L7&"); ","")&IF(N7<>"OK","Invalid Stock ("&N7&"); ","")) | Q7: =IF(O7=0,"Ready to List",IF(O7=1,"Needs Review","Incomplete")) -> Ready to List
A8: 11 | B8: AMC-103 | C8: =IF(B8="","",IF(COUNTIF($B$2:$B$50,B8)>1,"Duplicate SKU","")) | D8: Pashmina Ceruty Premium | E8: Hijab | F8: =IFERROR(VLOOKUP(E8,'Category Mapping'!$A$2:$B$23,2,FALSE()),"NOT MAPPED") -> Hijab | G8: Navy Blue | H8: =IF(TRIM(G8)="","",PROPER(TRIM(G8))) -> Navy Blue | I8: Free Size | J8: =IFERROR(VLOOKUP(I8,'Size Mapping'!$A$2:$B$19,2,FALSE()),"NOT MAPPED") -> All Size | L8: =IF(ISBLANK(K8),"Missing",IF(NOT(ISNUMBER(K8)),"Non-numeric",IF(K8<=0,"Invalid (<=0)","OK"))) -> Missing | M8: 22 | N8: =IF(ISBLANK(M8),"Missing",IF(NOT(ISNUMBER(M8)),"Non-numeric",IF(M8<0,"Invalid (negative)","OK"))) -> OK | O8: =IF(B8="",1,0)+IF(C8="Duplicate SKU",1,0)+IF(D8="",1,0)+IF(LEFT(F8,10)="NOT MAPPED",1,0)+IF(LEFT(J8,10)="NOT MAPPED",1,0)+IF(L8="OK",0,1)+IF(N8="OK",0,1) -> 1 | P8: =IF(RIGHT(IF(B8="","Missing SKU; ","")&IF(C8="Duplicate SKU","Duplicate SKU; ","")&IF(D8="","Missing Product Name; ","")&IF(LEFT(F8,10)="NOT MAPPED","Invalid Category ("&E8&"); ","")&IF(LEFT(J8,10)="NOT MAPPED","Invalid Size ("&I8&"); ","")&IF(L8<>"OK","Invalid Price ("&L8&"); ","")&IF(N8<>"OK","Invalid Stock ("&N8&"); ",""),2)="; ",LEFT(IF(B8="","Missing SKU; ","")&IF(C8="Duplicate SKU","Duplicate SKU; ","")&IF(D8="","Missing Product Name; ","")&IF(LEFT(F8,10)="NOT MAPPED","Invalid Category ("&E8&"); ","")&IF(LEFT(J8,10)="NOT MAPPED","Invalid Size ("&I8&"); ","")&IF(L8<>"OK","Invalid Price ("&L8&"); ","")&IF(N8<>"OK","Invalid Stock ("&N8&"); ",""),LEN(IF(B8="","Missing SKU; ","")&IF(C8="Duplicate SKU","Duplicate SKU; ","")&IF(D8="","Missing Product Name; ","")&IF(LEFT(F8,10)="NOT MAPPED","Invalid Category ("&E8&"); ","")&IF(LEFT(J8,10)="NOT MAPPED","Invalid Size ("&I8&"); ","")&IF(L8<>"OK","Invalid Price ("&L8&"); ","")&IF(N8<>"OK","Invalid Stock ("&N8&"); ",""))-2),IF(B8="","Missing SKU; ","")&IF(C8="Duplicate SKU","Duplicate SKU; ","")&IF(D8="","Missing Product Name; ","")&IF(LEFT(F8,10)="NOT MAPPED","Invalid Category ("&E8&"); ","")&IF(LEFT(J8,10)="NOT MAPPED","Invalid Size ("&I8&"); ","")&IF(L8<>"OK","Invalid Price ("&L8&"); ","")&IF(N8<>"OK","Invalid Stock ("&N8&"); ","")) -> Invalid Price (Missing) | Q8: =IF(O8=0,"Ready to List",IF(O8=1,"Needs Review","Incomplete")) -> Needs Review
A9: 12 | B9: AMC-113 | C9: =IF(B9="","",IF(COUNTIF($B$2:$B$50,B9)>1,"Duplicate SKU","")) | D9: Abaya Embroidered Kimono | E9: Abaya | F9: =IFERROR(VLOOKUP(E9,'Category Mapping'!$A$2:$B$23,2,FALSE()),"NOT MAPPED") -> Abaya | G9: Dusty Blue | H9: =IF(TRIM(G9)="","",PROPER(TRIM(G9))) -> Dusty Blue | I9: m | J9: =IFERROR(VLOOKUP(I9,'Size Mapping'!$A$2:$B$19,2,FALSE()),"NOT MAPPED") -> M | K9: 45 | L9: =IF(ISBLANK(K9),"Missing",IF(NOT(ISNUMBER(K9)),"Non-numeric",IF(K9<=0,"Invalid (<=0)","OK"))) -> OK | M9: 6 | N9: =IF(ISBLANK(M9),"Missing",IF(NOT(ISNUMBER(M9)),"Non-numeric",IF(M9<0,"Invalid (negative)","OK"))) -> OK | O9: =IF(B9="",1,0)+IF(C9="Duplicate SKU",1,0)+IF(D9="",1,0)+IF(LEFT(F9,10)="NOT MAPPED",1,0)+IF(LEFT(J9,10)="NOT MAPPED",1,0)+IF(L9="OK",0,1)+IF(N9="OK",0,1) -> 0 | P9: =IF(RIGHT(IF(B9="","Missing SKU; ","")&IF(C9="Duplicate SKU","Duplicate SKU; ","")&IF(D9="","Missing Product Name; ","")&IF(LEFT(F9,10)="NOT MAPPED","Invalid Category ("&E9&"); ","")&IF(LEFT(J9,10)="NOT MAPPED","Invalid Size ("&I9&"); ","")&IF(L9<>"OK","Invalid Price ("&L9&"); ","")&IF(N9<>"OK","Invalid Stock ("&N9&"); ",""),2)="; ",LEFT(IF(B9="","Missing SKU; ","")&IF(C9="Duplicate SKU","Duplicate SKU; ","")&IF(D9="","Missing Product Name; ","")&IF(LEFT(F9,10)="NOT MAPPED","Invalid Category ("&E9&"); ","")&IF(LEFT(J9,10)="NOT MAPPED","Invalid Size ("&I9&"); ","")&IF(L9<>"OK","Invalid Price ("&L9&"); ","")&IF(N9<>"OK","Invalid Stock ("&N9&"); ",""),LEN(IF(B9="","Missing SKU; ","")&IF(C9="Duplicate SKU","Duplicate SKU; ","")&IF(D9="","Missing Product Name; ","")&IF(LEFT(F9,10)="NOT MAPPED","Invalid Category ("&E9&"); ","")&IF(LEFT(J9,10)="NOT MAPPED","Invalid Size ("&I9&"); ","")&IF(L9<>"OK","Invalid Price ("&L9&"); ","")&IF(N9<>"OK","Invalid Stock ("&N9&"); ",""))-2),IF(B9="","Missing SKU; ","")&IF(C9="Duplicate SKU","Duplicate SKU; ","")&IF(D9="","Missing Product Name; ","")&IF(LEFT(F9,10)="NOT MAPPED","Invalid Category ("&E9&"); ","")&IF(LEFT(J9,10)="NOT MAPPED","Invalid Size ("&I9&"); ","")&IF(L9<>"OK","Invalid Price ("&L9&"); ","")&IF(N9<>"OK","Invalid Stock ("&N9&"); ","")) | Q9: =IF(O9=0,"Ready to List",IF(O9=1,"Needs Review","Incomplete")) -> Ready to List
A10: 13 | B10: AMC-114 | C10: =IF(B10="","",IF(COUNTIF($B$2:$B$50,B10)>1,"Duplicate SKU","")) -> Duplicate SKU | D10: Mukena Katun Jepang | E10: Prayer Set | F10: =IFERROR(VLOOKUP(E10,'Category Mapping'!$A$2:$B$23,2,FALSE()),"NOT MAPPED") -> Prayer Set | G10: Dusty Pink | H10: =IF(TRIM(G10)="","",PROPER(TRIM(G10))) -> Dusty Pink | I10: AllSize | J10: =IFERROR(VLOOKUP(I10,'Size Mapping'!$A$2:$B$19,2,FALSE()),"NOT MAPPED") -> All Size | K10: 28 | L10: =IF(ISBLANK(K10),"Missing",IF(NOT(ISNUMBER(K10)),"Non-numeric",IF(K10<=0,"Invalid (<=0)","OK"))) -> OK | M10: 12 | N10: =IF(ISBLANK(M10),"Missing",IF(NOT(ISNUMBER(M10)),"Non-numeric",IF(M10<0,"Invalid (negative)","OK"))) -> OK | O10: =IF(B10="",1,0)+IF(C10="Duplicate SKU",1,0)+IF(D10="",1,0)+IF(LEFT(F10,10)="NOT MAPPED",1,0)+IF(LEFT(J10,10)="NOT MAPPED",1,0)+IF(L10="OK",0,1)+IF(N10="OK",0,1) -> 1 | P10: =IF(RIGHT(IF(B10="","Missing SKU; ","")&IF(C10="Duplicate SKU","Duplicate SKU; ","")&IF(D10="","Missing Product Name; ","")&IF(LEFT(F10,10)="NOT MAPPED","Invalid Category ("&E10&"); ","")&IF(LEFT(J10,10)="NOT MAPPED","Invalid Size ("&I10&"); ","")&IF(L10<>"OK","Invalid Price ("&L10&"); ","")&IF(N10<>"OK","Invalid Stock ("&N10&"); ",""),2)="; ",LEFT(IF(B10="","Missing SKU; ","")&IF(C10="Duplicate SKU","Duplicate SKU; ","")&IF(D10="","Missing Product Name; ","")&IF(LEFT(F10,10)="NOT MAPPED","Invalid Category ("&E10&"); ","")&IF(LEFT(J10,10)="NOT MAPPED","Invalid Size ("&I10&"); ","")&IF(L10<>"OK","Invalid Price ("&L10&"); ","")&IF(N10<>"OK","Invalid Stock ("&N10&"); ",""),LEN(IF(B10="","Missing SKU; ","")&IF(C10="Duplicate SKU","Duplicate SKU; ","")&IF(D10="","Missing Product Name; ","")&IF(LEFT(F10,10)="NOT MAPPED","Invalid Category ("&E10&"); ","")&IF(LEFT(J10,10)="NOT MAPPED","Invalid Size ("&I10&"); ","")&IF(L10<>"OK","Invalid Price ("&L10&"); ","")&IF(N10<>"OK","Invalid Stock ("&N10&"); ",""))-2),IF(B10="","Missing SKU; ","")&IF(C10="Duplicate SKU","Duplicate SKU; ","")&IF(D10="","Missing Product Name; ","")&IF(LEFT(F10,10)="NOT MAPPED","Invalid Category ("&E10&"); ","")&IF(LEFT(J10,10)="NOT MAPPED","Invalid Size ("&I10&"); ","")&IF(L10<>"OK","Invalid Price ("&L10&"); ","")&IF(N10<>"OK","Invalid Stock ("&N10&"); ","")) -> Duplicate SKU | Q10: =IF(O10=0,"Ready to List",IF(O10=1,"Needs Review","Incomplete")) -> Needs Review
A11: 14 | B11: AMC-124 | C11: =IF(B11="","",IF(COUNTIF($B$2:$B$50,B11)>1,"Duplicate SKU","")) | E11: Accesories | F11: =IFERROR(VLOOKUP(E11,'Category Mapping'!$A$2:$B$23,2,FALSE()),"NOT MAPPED") -> Accessories | G11: Gold | H11: =IF(TRIM(G11)="","",PROPER(TRIM(G11))) -> Gold | I11: All Size | J11: =IFERROR(VLOOKUP(I11,'Size Mapping'!$A$2:$B$19,2,FALSE()),"NOT MAPPED") -> All Size | K11: 3.5 | L11: =IF(ISBLANK(K11),"Missing",IF(NOT(ISNUMBER(K11)),"Non-numeric",IF(K11<=0,"Invalid (<=0)","OK"))) -> OK | M11: 50 | N11: =IF(ISBLANK(M11),"Missing",IF(NOT(ISNUMBER(M11)),"Non-numeric",IF(M11<0,"Invalid (negative)","OK"))) -> OK | O11: =IF(B11="",1,0)+IF(C11="Duplicate SKU",1,0)+IF(D11="",1,0)+IF(LEFT(F11,10)="NOT MAPPED",1,0)+IF(LEFT(J11,10)="NOT MAPPED",1,0)+IF(L11="OK",0,1)+IF(N11="OK",0,1) -> 1 | P11: =IF(RIGHT(IF(B11="","Missing SKU; ","")&IF(C11="Duplicate SKU","Duplicate SKU; ","")&IF(D11="","Missing Product Name; ","")&IF(LEFT(F11,10)="NOT MAPPED","Invalid Category ("&E11&"); ","")&IF(LEFT(J11,10)="NOT MAPPED","Invalid Size ("&I11&"); ","")&IF(L11<>"OK","Invalid Price ("&L11&"); ","")&IF(N11<>"OK","Invalid Stock ("&N11&"); ",""),2)="; ",LEFT(IF(B11="","Missing SKU; ","")&IF(C11="Duplicate SKU","Duplicate SKU; ","")&IF(D11="","Missing Product Name; ","")&IF(LEFT(F11,10)="NOT MAPPED","Invalid Category ("&E11&"); ","")&IF(LEFT(J11,10)="NOT MAPPED","Invalid Size ("&I11&"); ","")&IF(L11<>"OK","Invalid Price ("&L11&"); ","")&IF(N11<>"OK","Invalid Stock ("&N11&"); ",""),LEN(IF(B11="","Missing SKU; ","")&IF(C11="Duplicate SKU","Duplicate SKU; ","")&IF(D11="","Missing Product Name; ","")&IF(LEFT(F11,10)="NOT MAPPED","Invalid Category ("&E11&"); ","")&IF(LEFT(J11,10)="NOT MAPPED","Invalid Size ("&I11&"); ","")&IF(L11<>"OK","Invalid Price ("&L11&"); ","")&IF(N11<>"OK","Invalid Stock ("&N11&"); ",""))-2),IF(B11="","Missing SKU; ","")&IF(C11="Duplicate SKU","Duplicate SKU; ","")&IF(D11="","Missing Product Name; ","")&IF(LEFT(F11,10)="NOT MAPPED","Invalid Category ("&E11&"); ","")&IF(LEFT(J11,10)="NOT MAPPED","Invalid Size ("&I11&"); ","")&IF(L11<>"OK","Invalid Price ("&L11&"); ","")&IF(N11<>"OK","Invalid Stock ("&N11&"); ","")) -> Missing Product Name | Q11: =IF(O11=0,"Ready to List",IF(O11=1,"Needs Review","Incomplete")) -> Needs Review
A12: 15 | B12: AMC-117 | C12: =IF(B12="","",IF(COUNTIF($B$2:$B$50,B12)>1,"Duplicate SKU","")) | D12: mukena rayon premium | E12: PrayerSet | F12: =IFERROR(VLOOKUP(E12,'Category Mapping'!$A$2:$B$23,2,FALSE()),"NOT MAPPED") -> Prayer Set | G12: LAVENDER | H12: =IF(TRIM(G12)="","",PROPER(TRIM(G12))) -> Lavender | I12: All size | J12: =IFERROR(VLOOKUP(I12,'Size Mapping'!$A$2:$B$19,2,FALSE()),"NOT MAPPED") -> All Size | K12: 32 | L12: =IF(ISBLANK(K12),"Missing",IF(NOT(ISNUMBER(K12)),"Non-numeric",IF(K12<=0,"Invalid (<=0)","OK"))) -> OK | M12: 13 | N12: =IF(ISBLANK(M12),"Missing",IF(NOT(ISNUMBER(M12)),"Non-numeric",IF(M12<0,"Invalid (negative)","OK"))) -> OK | O12: =IF(B12="",1,0)+IF(C12="Duplicate SKU",1,0)+IF(D12="",1,0)+IF(LEFT(F12,10)="NOT MAPPED",1,0)+IF(LEFT(J12,10)="NOT MAPPED",1,0)+IF(L12="OK",0,1)+IF(N12="OK",0,1) -> 0 | P12: =IF(RIGHT(IF(B12="","Missing SKU; ","")&IF(C12="Duplicate SKU","Duplicate SKU; ","")&IF(D12="","Missing Product Name; ","")&IF(LEFT(F12,10)="NOT MAPPED","Invalid Category ("&E12&"); ","")&IF(LEFT(J12,10)="NOT MAPPED","Invalid Size ("&I12&"); ","")&IF(L12<>"OK","Invalid Price ("&L12&"); ","")&IF(N12<>"OK","Invalid Stock ("&N12&"); ",""),2)="; ",LEFT(IF(B12="","Missing SKU; ","")&IF(C12="Duplicate SKU","Duplicate SKU; ","")&IF(D12="","Missing Product Name; ","")&IF(LEFT(F12,10)="NOT MAPPED","Invalid Category ("&E12&"); ","")&IF(LEFT(J12,10)="NOT MAPPED","Invalid Size ("&I12&"); ","")&IF(L12<>"OK","Invalid Price ("&L12&"); ","")&IF(N12<>"OK","Invalid Stock ("&N12&"); ",""),LEN(IF(B12="","Missing SKU; ","")&IF(C12="Duplicate SKU","Duplicate SKU; ","")&IF(D12="","Missing Product Name; ","")&IF(LEFT(F12,10)="NOT MAPPED","Invalid Category ("&E12&"); ","")&IF(LEFT(J12,10)="NOT MAPPED","Invalid Size ("&I12&"); ","")&IF(L12<>"OK","Invalid Price ("&L12&"); ","")&IF(N12<>"OK","Invalid Stock ("&N12&"); ",""))-2),IF(B12="","Missing SKU; ","")&IF(C12="Duplicate SKU","Duplicate SKU; ","")&IF(D12="","Missing Product Name; ","")&IF(LEFT(F12,10)="NOT MAPPED","Invalid Category ("&E12&"); ","")&IF(LEFT(J12,10)="NOT MAPPED","Invalid Size ("&I12&"); ","")&IF(L12<>"OK","Invalid Price ("&L12&"); ","")&IF(N12<>"OK","Invalid Stock ("&N12&"); ","")) | Q12: =IF(O12=0,"Ready to List",IF(O12=1,"Needs Review","Incomplete")) -> Ready to List
A13: 16 | B13: AMC-120 | C13: =IF(B13="","",IF(COUNTIF($B$2:$B$50,B13)>1,"Duplicate SKU","")) | D13: Ciput Antem Rajut | E13: Accessories | F13: =IFERROR(VLOOKUP(E13,'Category Mapping'!$A$2:$B$23,2,FALSE()),"NOT MAPPED") -> Accessories | G13: Black | H13: =IF(TRIM(G13)="","",PROPER(TRIM(G13))) -> Black | I13: ALLSIZE | J13: =IFERROR(VLOOKUP(I13,'Size Mapping'!$A$2:$B$19,2,FALSE()),"NOT MAPPED") -> All Size | K13: 4 | L13: =IF(ISBLANK(K13),"Missing",IF(NOT(ISNUMBER(K13)),"Non-numeric",IF(K13<=0,"Invalid (<=0)","OK"))) -> OK | M13: 45 | N13: =IF(ISBLANK(M13),"Missing",IF(NOT(ISNUMBER(M13)),"Non-numeric",IF(M13<0,"Invalid (negative)","OK"))) -> OK | O13: =IF(B13="",1,0)+IF(C13="Duplicate SKU",1,0)+IF(D13="",1,0)+IF(LEFT(F13,10)="NOT MAPPED",1,0)+IF(LEFT(J13,10)="NOT MAPPED",1,0)+IF(L13="OK",0,1)+IF(N13="OK",0,1) -> 0 | P13: =IF(RIGHT(IF(B13="","Missing SKU; ","")&IF(C13="Duplicate SKU","Duplicate SKU; ","")&IF(D13="","Missing Product Name; ","")&IF(LEFT(F13,10)="NOT MAPPED","Invalid Category ("&E13&"); ","")&IF(LEFT(J13,10)="NOT MAPPED","Invalid Size ("&I13&"); ","")&IF(L13<>"OK","Invalid Price ("&L13&"); ","")&IF(N13<>"OK","Invalid Stock ("&N13&"); ",""),2)="; ",LEFT(IF(B13="","Missing SKU; ","")&IF(C13="Duplicate SKU","Duplicate SKU; ","")&IF(D13="","Missing Product Name; ","")&IF(LEFT(F13,10)="NOT MAPPED","Invalid Category ("&E13&"); ","")&IF(LEFT(J13,10)="NOT MAPPED","Invalid Size ("&I13&"); ","")&IF(L13<>"OK","Invalid Price ("&L13&"); ","")&IF(N13<>"OK","Invalid Stock ("&N13&"); ",""),LEN(IF(B13="","Missing SKU; ","")&IF(C13="Duplicate SKU","Duplicate SKU; ","")&IF(D13="","Missing Product Name; ","")&IF(LEFT(F13,10)="NOT MAPPED","Invalid Category ("&E13&"); ","")&IF(LEFT(J13,10)="NOT MAPPED","Invalid Size ("&I13&"); ","")&IF(L13<>"OK","Invalid Price ("&L13&"); ","")&IF(N13<>"OK","Invalid Stock ("&N13&"); ",""))-2),IF(B13="","Missing SKU; ","")&IF(C13="Duplicate SKU","Duplicate SKU; ","")&IF(D13="","Missing Product Name; ","")&IF(LEFT(F13,10)="NOT MAPPED","Invalid Category ("&E13&"); ","")&IF(LEFT(J13,10)="NOT MAPPED","Invalid Size ("&I13&"); ","")&IF(L13<>"OK","Invalid Price ("&L13&"); ","")&IF(N13<>"OK","Invalid Stock ("&N13&"); ","")) | Q13: =IF(O13=0,"Ready to List",IF(O13=1,"Needs Review","Incomplete")) -> Ready to List
A14: 17 | B14: AMC-115 | C14: =IF(B14="","",IF(COUNTIF($B$2:$B$50,B14)>1,"Duplicate SKU","")) | D14: Open Abaya Cardigan Style | E14: Abaya | F14: =IFERROR(VLOOKUP(E14,'Category Mapping'!$A$2:$B$23,2,FALSE()),"NOT MAPPED") -> Abaya | G14: Sand | H14: =IF(TRIM(G14)="","",PROPER(TRIM(G14))) -> Sand | I14: Free Size | J14: =IFERROR(VLOOKUP(I14,'Size Mapping'!$A$2:$B$19,2,FALSE()),"NOT MAPPED") -> All Size | K14: 41 | L14: =IF(ISBLANK(K14),"Missing",IF(NOT(ISNUMBER(K14)),"Non-numeric",IF(K14<=0,"Invalid (<=0)","OK"))) -> OK | M14: 11 | N14: =IF(ISBLANK(M14),"Missing",IF(NOT(ISNUMBER(M14)),"Non-numeric",IF(M14<0,"Invalid (negative)","OK"))) -> OK | O14: =IF(B14="",1,0)+IF(C14="Duplicate SKU",1,0)+IF(D14="",1,0)+IF(LEFT(F14,10)="NOT MAPPED",1,0)+IF(LEFT(J14,10)="NOT MAPPED",1,0)+IF(L14="OK",0,1)+IF(N14="OK",0,1) -> 0 | P14: =IF(RIGHT(IF(B14="","Missing SKU; ","")&IF(C14="Duplicate SKU","Duplicate SKU; ","")&IF(D14="","Missing Product Name; ","")&IF(LEFT(F14,10)="NOT MAPPED","Invalid Category ("&E14&"); ","")&IF(LEFT(J14,10)="NOT MAPPED","Invalid Size ("&I14&"); ","")&IF(L14<>"OK","Invalid Price ("&L14&"); ","")&IF(N14<>"OK","Invalid Stock ("&N14&"); ",""),2)="; ",LEFT(IF(B14="","Missing SKU; ","")&IF(C14="Duplicate SKU","Duplicate SKU; ","")&IF(D14="","Missing Product Name; ","")&IF(LEFT(F14,10)="NOT MAPPED","Invalid Category ("&E14&"); ","")&IF(LEFT(J14,10)="NOT MAPPED","Invalid Size ("&I14&"); ","")&IF(L14<>"OK","Invalid Price ("&L14&"); ","")&IF(N14<>"OK","Invalid Stock ("&N14&"); ",""),LEN(IF(B14="","Missing SKU; ","")&IF(C14="Duplicate SKU","Duplicate SKU; ","")&IF(D14="","Missing Product Name; ","")&IF(LEFT(F14,10)="NOT MAPPED","Invalid Category ("&E14&"); ","")&IF(LEFT(J14,10)="NOT MAPPED","Invalid Size ("&I14&"); ","")&IF(L14<>"OK","Invalid Price ("&L14&"); ","")&IF(N14<>"OK","Invalid Stock ("&N14&"); ",""))-2),IF(B14="","Missing SKU; ","")&IF(C14="Duplicate SKU","Duplicate SKU; ","")&IF(D14="","Missing Product Name; ","")&IF(LEFT(F14,10)="NOT MAPPED","Invalid Category ("&E14&"); ","")&IF(LEFT(J14,10)="NOT MAPPED","Invalid Size ("&I14&"); ","")&IF(L14<>"OK","Invalid Price ("&L14&"); ","")&IF(N14<>"OK","Invalid Stock ("&N14&"); ","")) | Q14: =IF(O14=0,"Ready to List",IF(O14=1,"Needs Review","Incomplete")) -> Ready to List
A15: 18 | B15: AMC-104 | C15: =IF(B15="","",IF(COUNTIF($B$2:$B$50,B15)>1,"Duplicate SKU","")) | D15: Bergo Instan Ceruty | E15: Hijab | F15: =IFERROR(VLOOKUP(E15,'Category Mapping'!$A$2:$B$23,2,FALSE()),"NOT MAPPED") -> Hijab | G15: Black | H15: =IF(TRIM(G15)="","",PROPER(TRIM(G15))) -> Black | I15: AllSize | J15: =IFERROR(VLOOKUP(I15,'Size Mapping'!$A$2:$B$19,2,FALSE()),"NOT MAPPED") -> All Size | K15: 10 | L15: =IF(ISBLANK(K15),"Missing",IF(NOT(ISNUMBER(K15)),"Non-numeric",IF(K15<=0,"Invalid (<=0)","OK"))) -> OK | M15: 40 | N15: =IF(ISBLANK(M15),"Missing",IF(NOT(ISNUMBER(M15)),"Non-numeric",IF(M15<0,"Invalid (negative)","OK"))) -> OK | O15: =IF(B15="",1,0)+IF(C15="Duplicate SKU",1,0)+IF(D15="",1,0)+IF(LEFT(F15,10)="NOT MAPPED",1,0)+IF(LEFT(J15,10)="NOT MAPPED",1,0)+IF(L15="OK",0,1)+IF(N15="OK",0,1) -> 0 | P15: =IF(RIGHT(IF(B15="","Missing SKU; ","")&IF(C15="Duplicate SKU","Duplicate SKU; ","")&IF(D15="","Missing Product Name; ","")&IF(LEFT(F15,10)="NOT MAPPED","Invalid Category ("&E15&"); ","")&IF(LEFT(J15,10)="NOT MAPPED","Invalid Size ("&I15&"); ","")&IF(L15<>"OK","Invalid Price ("&L15&"); ","")&IF(N15<>"OK","Invalid Stock ("&N15&"); ",""),2)="; ",LEFT(IF(B15="","Missing SKU; ","")&IF(C15="Duplicate SKU","Duplicate SKU; ","")&IF(D15="","Missing Product Name; ","")&IF(LEFT(F15,10)="NOT MAPPED","Invalid Category ("&E15&"); ","")&IF(LEFT(J15,10)="NOT MAPPED","Invalid Size ("&I15&"); ","")&IF(L15<>"OK","Invalid Price ("&L15&"); ","")&IF(N15<>"OK","Invalid Stock ("&N15&"); ",""),LEN(IF(B15="","Missing SKU; ","")&IF(C15="Duplicate SKU","Duplicate SKU; ","")&IF(D15="","Missing Product Name; ","")&IF(LEFT(F15,10)="NOT MAPPED","Invalid Category ("&E15&"); ","")&IF(LEFT(J15,10)="NOT MAPPED","Invalid Size ("&I15&"); ","")&IF(L15<>"OK","Invalid Price ("&L15&"); ","")&IF(N15<>"OK","Invalid Stock ("&N15&"); ",""))-2),IF(B15="","Missing SKU; ","")&IF(C15="Duplicate SKU","Duplicate SKU; ","")&IF(D15="","Missing Product Name; ","")&IF(LEFT(F15,10)="NOT MAPPED","Invalid Category ("&E15&"); ","")&IF(LEFT(J15,10)="NOT MAPPED","Invalid Size ("&I15&"); ","")&IF(L15<>"OK","Invalid Price ("&L15&"); ","")&IF(N15<>"OK","Invalid Stock ("&N15&"); ","")) | Q15: =IF(O15=0,"Ready to List",IF(O15=1,"Needs Review","Incomplete")) -> Ready to List
A16: 19 | B16: AMC-118 | C16: =IF(B16="","",IF(COUNTIF($B$2:$B$50,B16)>1,"Duplicate SKU","")) | D16: Sajadah Travel Roll | E16: Prayer set | F16: =IFERROR(VLOOKUP(E16,'Category Mapping'!$A$2:$B$23,2,FALSE()),"NOT MAPPED") -> Prayer Set | G16: Grey | H16: =IF(TRIM(G16)="","",PROPER(TRIM(G16))) -> Grey | I16: All Size | J16: =IFERROR(VLOOKUP(I16,'Size Mapping'!$A$2:$B$19,2,FALSE()),"NOT MAPPED") -> All Size | K16: 9 | L16: =IF(ISBLANK(K16),"Missing",IF(NOT(ISNUMBER(K16)),"Non-numeric",IF(K16<=0,"Invalid (<=0)","OK"))) -> OK | M16: 25 | N16: =IF(ISBLANK(M16),"Missing",IF(NOT(ISNUMBER(M16)),"Non-numeric",IF(M16<0,"Invalid (negative)","OK"))) -> OK | O16: =IF(B16="",1,0)+IF(C16="Duplicate SKU",1,0)+IF(D16="",1,0)+IF(LEFT(F16,10)="NOT MAPPED",1,0)+IF(LEFT(J16,10)="NOT MAPPED",1,0)+IF(L16="OK",0,1)+IF(N16="OK",0,1) -> 0 | P16: =IF(RIGHT(IF(B16="","Missing SKU; ","")&IF(C16="Duplicate SKU","Duplicate SKU; ","")&IF(D16="","Missing Product Name; ","")&IF(LEFT(F16,10)="NOT MAPPED","Invalid Category ("&E16&"); ","")&IF(LEFT(J16,10)="NOT MAPPED","Invalid Size ("&I16&"); ","")&IF(L16<>"OK","Invalid Price ("&L16&"); ","")&IF(N16<>"OK","Invalid Stock ("&N16&"); ",""),2)="; ",LEFT(IF(B16="","Missing SKU; ","")&IF(C16="Duplicate SKU","Duplicate SKU; ","")&IF(D16="","Missing Product Name; ","")&IF(LEFT(F16,10)="NOT MAPPED","Invalid Category ("&E16&"); ","")&IF(LEFT(J16,10)="NOT MAPPED","Invalid Size ("&I16&"); ","")&IF(L16<>"OK","Invalid Price ("&L16&"); ","")&IF(N16<>"OK","Invalid Stock ("&N16&"); ",""),LEN(IF(B16="","Missing SKU; ","")&IF(C16="Duplicate SKU","Duplicate SKU; ","")&IF(D16="","Missing Product Name; ","")&IF(LEFT(F16,10)="NOT MAPPED","Invalid Category ("&E16&"); ","")&IF(LEFT(J16,10)="NOT MAPPED","Invalid Size ("&I16&"); ","")&IF(L16<>"OK","Invalid Price ("&L16&"); ","")&IF(N16<>"OK","Invalid Stock ("&N16&"); ",""))-2),IF(B16="","Missing SKU; ","")&IF(C16="Duplicate SKU","Duplicate SKU; ","")&IF(D16="","Missing Product Name; ","")&IF(LEFT(F16,10)="NOT MAPPED","Invalid Category ("&E16&"); ","")&IF(LEFT(J16,10)="NOT MAPPED","Invalid Size ("&I16&"); ","")&IF(L16<>"OK","Invalid Price ("&L16&"); ","")&IF(N16<>"OK","Invalid Stock ("&N16&"); ","")) | Q16: =IF(O16=0,"Ready to List",IF(O16=1,"Needs Review","Incomplete")) -> Ready to List
A17: 20 | B17: AMC-122 | C17: =IF(B17="","",IF(COUNTIF($B$2:$B$50,B17)>1,"Duplicate SKU","")) -> Duplicate SKU | D17: Manset Baju Kaos | E17: Accessory | F17: =IFERROR(VLOOKUP(E17,'Category Mapping'!$A$2:$B$23,2,FALSE()),"NOT MAPPED") -> Accessories | G17: NUDE | H17: =IF(TRIM(G17)="","",PROPER(TRIM(G17))) -> Nude | I17: AllSize | J17: =IFERROR(VLOOKUP(I17,'Size Mapping'!$A$2:$B$19,2,FALSE()),"NOT MAPPED") -> All Size | K17: 5 | L17: =IF(ISBLANK(K17),"Missing",IF(NOT(ISNUMBER(K17)),"Non-numeric",IF(K17<=0,"Invalid (<=0)","OK"))) -> OK | M17: 33 | N17: =IF(ISBLANK(M17),"Missing",IF(NOT(ISNUMBER(M17)),"Non-numeric",IF(M17<0,"Invalid (negative)","OK"))) -> OK | O17: =IF(B17="",1,0)+IF(C17="Duplicate SKU",1,0)+IF(D17="",1,0)+IF(LEFT(F17,10)="NOT MAPPED",1,0)+IF(LEFT(J17,10)="NOT MAPPED",1,0)+IF(L17="OK",0,1)+IF(N17="OK",0,1) -> 1 | P17: =IF(RIGHT(IF(B17="","Missing SKU; ","")&IF(C17="Duplicate SKU","Duplicate SKU; ","")&IF(D17="","Missing Product Name; ","")&IF(LEFT(F17,10)="NOT MAPPED","Invalid Category ("&E17&"); ","")&IF(LEFT(J17,10)="NOT MAPPED","Invalid Size ("&I17&"); ","")&IF(L17<>"OK","Invalid Price ("&L17&"); ","")&IF(N17<>"OK","Invalid Stock ("&N17&"); ",""),2)="; ",LEFT(IF(B17="","Missing SKU; ","")&IF(C17="Duplicate SKU","Duplicate SKU; ","")&IF(D17="","Missing Product Name; ","")&IF(LEFT(F17,10)="NOT MAPPED","Invalid Category ("&E17&"); ","")&IF(LEFT(J17,10)="NOT MAPPED","Invalid Size ("&I17&"); ","")&IF(L17<>"OK","Invalid Price ("&L17&"); ","")&IF(N17<>"OK","Invalid Stock ("&N17&"); ",""),LEN(IF(B17="","Missing SKU; ","")&IF(C17="Duplicate SKU","Duplicate SKU; ","")&IF(D17="","Missing Product Name; ","")&IF(LEFT(F17,10)="NOT MAPPED","Invalid Category ("&E17&"); ","")&IF(LEFT(J17,10)="NOT MAPPED","Invalid Size ("&I17&"); ","")&IF(L17<>"OK","Invalid Price ("&L17&"); ","")&IF(N17<>"OK","Invalid Stock ("&N17&"); ",""))-2),IF(B17="","Missing SKU; ","")&IF(C17="Duplicate SKU","Duplicate SKU; ","")&IF(D17="","Missing Product Name; ","")&IF(LEFT(F17,10)="NOT MAPPED","Invalid Category ("&E17&"); ","")&IF(LEFT(J17,10)="NOT MAPPED","Invalid Size ("&I17&"); ","")&IF(L17<>"OK","Invalid Price ("&L17&"); ","")&IF(N17<>"OK","Invalid Stock ("&N17&"); ","")) -> Duplicate SKU | Q17: =IF(O17=0,"Ready to List",IF(O17=1,"Needs Review","Incomplete")) -> Needs Review
A18: 21 | B18: AMC-123 | C18: =IF(B18="","",IF(COUNTIF($B$2:$B$50,B18)>1,"Duplicate SKU","")) | D18: Manset Baju Kaos | E18: ACCESSORIES | F18: =IFERROR(VLOOKUP(E18,'Category Mapping'!$A$2:$B$23,2,FALSE()),"NOT MAPPED") -> Accessories | G18: White | H18: =IF(TRIM(G18)="","",PROPER(TRIM(G18))) -> White | I18: All size | J18: =IFERROR(VLOOKUP(I18,'Size Mapping'!$A$2:$B$19,2,FALSE()),"NOT MAPPED") -> All Size | K18: 5 | L18: =IF(ISBLANK(K18),"Missing",IF(NOT(ISNUMBER(K18)),"Non-numeric",IF(K18<=0,"Invalid (<=0)","OK"))) -> OK | M18: 29 | N18: =IF(ISBLANK(M18),"Missing",IF(NOT(ISNUMBER(M18)),"Non-numeric",IF(M18<0,"Invalid (negative)","OK"))) -> OK | O18: =IF(B18="",1,0)+IF(C18="Duplicate SKU",1,0)+IF(D18="",1,0)+IF(LEFT(F18,10)="NOT MAPPED",1,0)+IF(LEFT(J18,10)="NOT MAPPED",1,0)+IF(L18="OK",0,1)+IF(N18="OK",0,1) -> 0 | P18: =IF(RIGHT(IF(B18="","Missing SKU; ","")&IF(C18="Duplicate SKU","Duplicate SKU; ","")&IF(D18="","Missing Product Name; ","")&IF(LEFT(F18,10)="NOT MAPPED","Invalid Category ("&E18&"); ","")&IF(LEFT(J18,10)="NOT MAPPED","Invalid Size ("&I18&"); ","")&IF(L18<>"OK","Invalid Price ("&L18&"); ","")&IF(N18<>"OK","Invalid Stock ("&N18&"); ",""),2)="; ",LEFT(IF(B18="","Missing SKU; ","")&IF(C18="Duplicate SKU","Duplicate SKU; ","")&IF(D18="","Missing Product Name; ","")&IF(LEFT(F18,10)="NOT MAPPED","Invalid Category ("&E18&"); ","")&IF(LEFT(J18,10)="NOT MAPPED","Invalid Size ("&I18&"); ","")&IF(L18<>"OK","Invalid Price ("&L18&"); ","")&IF(N18<>"OK","Invalid Stock ("&N18&"); ",""),LEN(IF(B18="","Missing SKU; ","")&IF(C18="Duplicate SKU","Duplicate SKU; ","")&IF(D18="","Missing Product Name; ","")&IF(LEFT(F18,10)="NOT MAPPED","Invalid Category ("&E18&"); ","")&IF(LEFT(J18,10)="NOT MAPPED","Invalid Size ("&I18&"); ","")&IF(L18<>"OK","Invalid Price ("&L18&"); ","")&IF(N18<>"OK","Invalid Stock ("&N18&"); ",""))-2),IF(B18="","Missing SKU; ","")&IF(C18="Duplicate SKU","Duplicate SKU; ","")&IF(D18="","Missing Product Name; ","")&IF(LEFT(F18,10)="NOT MAPPED","Invalid Category ("&E18&"); ","")&IF(LEFT(J18,10)="NOT MAPPED","Invalid Size ("&I18&"); ","")&IF(L18<>"OK","Invalid Price ("&L18&"); ","")&IF(N18<>"OK","Invalid Stock ("&N18&"); ","")) | Q18: =IF(O18=0,"Ready to List",IF(O18=1,"Needs Review","Incomplete")) -> Ready to List
A19: 22 | B19: AMC-121 | C19: =IF(B19="","",IF(COUNTIF($B$2:$B$50,B19)>1,"Duplicate SKU","")) | D19: Ciput Antem Rajut | E19: accessories | F19: =IFERROR(VLOOKUP(E19,'Category Mapping'!$A$2:$B$23,2,FALSE()),"NOT MAPPED") -> Accessories | G19: cream | H19: =IF(TRIM(G19)="","",PROPER(TRIM(G19))) -> Cream | I19: Free Size | J19: =IFERROR(VLOOKUP(I19,'Size Mapping'!$A$2:$B$19,2,FALSE()),"NOT MAPPED") -> All Size | K19: 4 | L19: =IF(ISBLANK(K19),"Missing",IF(NOT(ISNUMBER(K19)),"Non-numeric",IF(K19<=0,"Invalid (<=0)","OK"))) -> OK | M19: 38 | N19: =IF(ISBLANK(M19),"Missing",IF(NOT(ISNUMBER(M19)),"Non-numeric",IF(M19<0,"Invalid (negative)","OK"))) -> OK | O19: =IF(B19="",1,0)+IF(C19="Duplicate SKU",1,0)+IF(D19="",1,0)+IF(LEFT(F19,10)="NOT MAPPED",1,0)+IF(LEFT(J19,10)="NOT MAPPED",1,0)+IF(L19="OK",0,1)+IF(N19="OK",0,1) -> 0 | P19: =IF(RIGHT(IF(B19="","Missing SKU; ","")&IF(C19="Duplicate SKU","Duplicate SKU; ","")&IF(D19="","Missing Product Name; ","")&IF(LEFT(F19,10)="NOT MAPPED","Invalid Category ("&E19&"); ","")&IF(LEFT(J19,10)="NOT MAPPED","Invalid Size ("&I19&"); ","")&IF(L19<>"OK","Invalid Price ("&L19&"); ","")&IF(N19<>"OK","Invalid Stock ("&N19&"); ",""),2)="; ",LEFT(IF(B19="","Missing SKU; ","")&IF(C19="Duplicate SKU","Duplicate SKU; ","")&IF(D19="","Missing Product Name; ","")&IF(LEFT(F19,10)="NOT MAPPED","Invalid Category ("&E19&"); ","")&IF(LEFT(J19,10)="NOT MAPPED","Invalid Size ("&I19&"); ","")&IF(L19<>"OK","Invalid Price ("&L19&"); ","")&IF(N19<>"OK","Invalid Stock ("&N19&"); ",""),LEN(IF(B19="","Missing SKU; ","")&IF(C19="Duplicate SKU","Duplicate SKU; ","")&IF(D19="","Missing Product Name; ","")&IF(LEFT(F19,10)="NOT MAPPED","Invalid Category ("&E19&"); ","")&IF(LEFT(J19,10)="NOT MAPPED","Invalid Size ("&I19&"); ","")&IF(L19<>"OK","Invalid Price ("&L19&"); ","")&IF(N19<>"OK","Invalid Stock ("&N19&"); ",""))-2),IF(B19="","Missing SKU; ","")&IF(C19="Duplicate SKU","Duplicate SKU; ","")&IF(D19="","Missing Product Name; ","")&IF(LEFT(F19,10)="NOT MAPPED","Invalid Category ("&E19&"); ","")&IF(LEFT(J19,10)="NOT MAPPED","Invalid Size ("&I19&"); ","")&IF(L19<>"OK","Invalid Price ("&L19&"); ","")&IF(N19<>"OK","Invalid Stock ("&N19&"); ","")) | Q19: =IF(O19=0,"Ready to List",IF(O19=1,"Needs Review","Incomplete")) -> Ready to List
A20: 23 | B20: AMC-131 | C20: =IF(B20="","",IF(COUNTIF($B$2:$B$50,B20)>1,"Duplicate SKU","")) | D20: Bergo Rabbani Syari | E20: hijab | F20: =IFERROR(VLOOKUP(E20,'Category Mapping'!$A$2:$B$23,2,FALSE()),"NOT MAPPED") -> Hijab | G20: brown | H20: =IF(TRIM(G20)="","",PROPER(TRIM(G20))) -> Brown | I20: XL | J20: =IFERROR(VLOOKUP(I20,'Size Mapping'!$A$2:$B$19,2,FALSE()),"NOT MAPPED") -> XL | K20: 14 | L20: =IF(ISBLANK(K20),"Missing",IF(NOT(ISNUMBER(K20)),"Non-numeric",IF(K20<=0,"Invalid (<=0)","OK"))) -> OK | M20: 9 | N20: =IF(ISBLANK(M20),"Missing",IF(NOT(ISNUMBER(M20)),"Non-numeric",IF(M20<0,"Invalid (negative)","OK"))) -> OK | O20: =IF(B20="",1,0)+IF(C20="Duplicate SKU",1,0)+IF(D20="",1,0)+IF(LEFT(F20,10)="NOT MAPPED",1,0)+IF(LEFT(J20,10)="NOT MAPPED",1,0)+IF(L20="OK",0,1)+IF(N20="OK",0,1) -> 0 | P20: =IF(RIGHT(IF(B20="","Missing SKU; ","")&IF(C20="Duplicate SKU","Duplicate SKU; ","")&IF(D20="","Missing Product Name; ","")&IF(LEFT(F20,10)="NOT MAPPED","Invalid Category ("&E20&"); ","")&IF(LEFT(J20,10)="NOT MAPPED","Invalid Size ("&I20&"); ","")&IF(L20<>"OK","Invalid Price ("&L20&"); ","")&IF(N20<>"OK","Invalid Stock ("&N20&"); ",""),2)="; ",LEFT(IF(B20="","Missing SKU; ","")&IF(C20="Duplicate SKU","Duplicate SKU; ","")&IF(D20="","Missing Product Name; ","")&IF(LEFT(F20,10)="NOT MAPPED","Invalid Category ("&E20&"); ","")&IF(LEFT(J20,10)="NOT MAPPED","Invalid Size ("&I20&"); ","")&IF(L20<>"OK","Invalid Price ("&L20&"); ","")&IF(N20<>"OK","Invalid Stock ("&N20&"); ",""),LEN(IF(B20="","Missing SKU; ","")&IF(C20="Duplicate SKU","Duplicate SKU; ","")&IF(D20="","Missing Product Name; ","")&IF(LEFT(F20,10)="NOT MAPPED","Invalid Category ("&E20&"); ","")&IF(LEFT(J20,10)="NOT MAPPED","Invalid Size ("&I20&"); ","")&IF(L20<>"OK","Invalid Price ("&L20&"); ","")&IF(N20<>"OK","Invalid Stock ("&N20&"); ",""))-2),IF(B20="","Missing SKU; ","")&IF(C20="Duplicate SKU","Duplicate SKU; ","")&IF(D20="","Missing Product Name; ","")&IF(LEFT(F20,10)="NOT MAPPED","Invalid Category ("&E20&"); ","")&IF(LEFT(J20,10)="NOT MAPPED","Invalid Size ("&I20&"); ","")&IF(L20<>"OK","Invalid Price ("&L20&"); ","")&IF(N20<>"OK","Invalid Stock ("&N20&"); ","")) | Q20: =IF(O20=0,"Ready to List",IF(O20=1,"Needs Review","Incomplete")) -> Ready to List
A21: 24 | B21: AMC-114 | C21: =IF(B21="","",IF(COUNTIF($B$2:$B$50,B21)>1,"Duplicate SKU","")) -> Duplicate SKU | D21: Abaya Embroidered Kimono | E21: Abayas | F21: =IFERROR(VLOOKUP(E21,'Category Mapping'!$A$2:$B$23,2,FALSE()),"NOT MAPPED") -> Abaya | G21: Dusty Blue | H21: =IF(TRIM(G21)="","",PROPER(TRIM(G21))) -> Dusty Blue | I21: L | J21: =IFERROR(VLOOKUP(I21,'Size Mapping'!$A$2:$B$19,2,FALSE()),"NOT MAPPED") -> L | K21: 45 | L21: =IF(ISBLANK(K21),"Missing",IF(NOT(ISNUMBER(K21)),"Non-numeric",IF(K21<=0,"Invalid (<=0)","OK"))) -> OK | M21: 5 | N21: =IF(ISBLANK(M21),"Missing",IF(NOT(ISNUMBER(M21)),"Non-numeric",IF(M21<0,"Invalid (negative)","OK"))) -> OK | O21: =IF(B21="",1,0)+IF(C21="Duplicate SKU",1,0)+IF(D21="",1,0)+IF(LEFT(F21,10)="NOT MAPPED",1,0)+IF(LEFT(J21,10)="NOT MAPPED",1,0)+IF(L21="OK",0,1)+IF(N21="OK",0,1) -> 1 | P21: =IF(RIGHT(IF(B21="","Missing SKU; ","")&IF(C21="Duplicate SKU","Duplicate SKU; ","")&IF(D21="","Missing Product Name; ","")&IF(LEFT(F21,10)="NOT MAPPED","Invalid Category ("&E21&"); ","")&IF(LEFT(J21,10)="NOT MAPPED","Invalid Size ("&I21&"); ","")&IF(L21<>"OK","Invalid Price ("&L21&"); ","")&IF(N21<>"OK","Invalid Stock ("&N21&"); ",""),2)="; ",LEFT(IF(B21="","Missing SKU; ","")&IF(C21="Duplicate SKU","Duplicate SKU; ","")&IF(D21="","Missing Product Name; ","")&IF(LEFT(F21,10)="NOT MAPPED","Invalid Category ("&E21&"); ","")&IF(LEFT(J21,10)="NOT MAPPED","Invalid Size ("&I21&"); ","")&IF(L21<>"OK","Invalid Price ("&L21&"); ","")&IF(N21<>"OK","Invalid Stock ("&N21&"); ",""),LEN(IF(B21="","Missing SKU; ","")&IF(C21="Duplicate SKU","Duplicate SKU; ","")&IF(D21="","Missing Product Name; ","")&IF(LEFT(F21,10)="NOT MAPPED","Invalid Category ("&E21&"); ","")&IF(LEFT(J21,10)="NOT MAPPED","Invalid Size ("&I21&"); ","")&IF(L21<>"OK","Invalid Price ("&L21&"); ","")&IF(N21<>"OK","Invalid Stock ("&N21&"); ",""))-2),IF(B21="","Missing SKU; ","")&IF(C21="Duplicate SKU","Duplicate SKU; ","")&IF(D21="","Missing Product Name; ","")&IF(LEFT(F21,10)="NOT MAPPED","Invalid Category ("&E21&"); ","")&IF(LEFT(J21,10)="NOT MAPPED","Invalid Size ("&I21&"); ","")&IF(L21<>"OK","Invalid Price ("&L21&"); ","")&IF(N21<>"OK","Invalid Stock ("&N21&"); ","")) -> Duplicate SKU | Q21: =IF(O21=0,"Ready to List",IF(O21=1,"Needs Review","Incomplete")) -> Needs Review
A22: 25 | B22: AMC-129 | C22: =IF(B22="","",IF(COUNTIF($B$2:$B$50,B22)>1,"Duplicate SKU","")) | D22: Pashmina Diamond Italiano | E22: Hijabs | F22: =IFERROR(VLOOKUP(E22,'Category Mapping'!$A$2:$B$23,2,FALSE()),"NOT MAPPED") -> Hijab | G22: Ivory | H22: =IF(TRIM(G22)="","",PROPER(TRIM(G22))) -> Ivory | I22: All size | J22: =IFERROR(VLOOKUP(I22,'Size Mapping'!$A$2:$B$19,2,FALSE()),"NOT MAPPED") -> All Size | K22: 12.5 | L22: =IF(ISBLANK(K22),"Missing",IF(NOT(ISNUMBER(K22)),"Non-numeric",IF(K22<=0,"Invalid (<=0)","OK"))) -> OK | M22: 20 | N22: =IF(ISBLANK(M22),"Missing",IF(NOT(ISNUMBER(M22)),"Non-numeric",IF(M22<0,"Invalid (negative)","OK"))) -> OK | O22: =IF(B22="",1,0)+IF(C22="Duplicate SKU",1,0)+IF(D22="",1,0)+IF(LEFT(F22,10)="NOT MAPPED",1,0)+IF(LEFT(J22,10)="NOT MAPPED",1,0)+IF(L22="OK",0,1)+IF(N22="OK",0,1) -> 0 | P22: =IF(RIGHT(IF(B22="","Missing SKU; ","")&IF(C22="Duplicate SKU","Duplicate SKU; ","")&IF(D22="","Missing Product Name; ","")&IF(LEFT(F22,10)="NOT MAPPED","Invalid Category ("&E22&"); ","")&IF(LEFT(J22,10)="NOT MAPPED","Invalid Size ("&I22&"); ","")&IF(L22<>"OK","Invalid Price ("&L22&"); ","")&IF(N22<>"OK","Invalid Stock ("&N22&"); ",""),2)="; ",LEFT(IF(B22="","Missing SKU; ","")&IF(C22="Duplicate SKU","Duplicate SKU; ","")&IF(D22="","Missing Product Name; ","")&IF(LEFT(F22,10)="NOT MAPPED","Invalid Category ("&E22&"); ","")&IF(LEFT(J22,10)="NOT MAPPED","Invalid Size ("&I22&"); ","")&IF(L22<>"OK","Invalid Price ("&L22&"); ","")&IF(N22<>"OK","Invalid Stock ("&N22&"); ",""),LEN(IF(B22="","Missing SKU; ","")&IF(C22="Duplicate SKU","Duplicate SKU; ","")&IF(D22="","Missing Product Name; ","")&IF(LEFT(F22,10)="NOT MAPPED","Invalid Category ("&E22&"); ","")&IF(LEFT(J22,10)="NOT MAPPED","Invalid Size ("&I22&"); ","")&IF(L22<>"OK","Invalid Price ("&L22&"); ","")&IF(N22<>"OK","Invalid Stock ("&N22&"); ",""))-2),IF(B22="","Missing SKU; ","")&IF(C22="Duplicate SKU","Duplicate SKU; ","")&IF(D22="","Missing Product Name; ","")&IF(LEFT(F22,10)="NOT MAPPED","Invalid Category ("&E22&"); ","")&IF(LEFT(J22,10)="NOT MAPPED","Invalid Size ("&I22&"); ","")&IF(L22<>"OK","Invalid Price ("&L22&"); ","")&IF(N22<>"OK","Invalid Stock ("&N22&"); ","")) | Q22: =IF(O22=0,"Ready to List",IF(O22=1,"Needs Review","Incomplete")) -> Ready to List
A23: 26 | B23: AMC-144 | C23: =IF(B23="","",IF(COUNTIF($B$2:$B$50,B23)>1,"Duplicate SKU","")) | D23: Inner Ninja Ciput | E23: Accesories | F23: =IFERROR(VLOOKUP(E23,'Category Mapping'!$A$2:$B$23,2,FALSE()),"NOT MAPPED") -> Accessories | G23: Nude | H23: =IF(TRIM(G23)="","",PROPER(TRIM(G23))) -> Nude | I23: ALLSIZE | J23: =IFERROR(VLOOKUP(I23,'Size Mapping'!$A$2:$B$19,2,FALSE()),"NOT MAPPED") -> All Size | K23: 4.5 | L23: =IF(ISBLANK(K23),"Missing",IF(NOT(ISNUMBER(K23)),"Non-numeric",IF(K23<=0,"Invalid (<=0)","OK"))) -> OK | M23: 22 | N23: =IF(ISBLANK(M23),"Missing",IF(NOT(ISNUMBER(M23)),"Non-numeric",IF(M23<0,"Invalid (negative)","OK"))) -> OK | O23: =IF(B23="",1,0)+IF(C23="Duplicate SKU",1,0)+IF(D23="",1,0)+IF(LEFT(F23,10)="NOT MAPPED",1,0)+IF(LEFT(J23,10)="NOT MAPPED",1,0)+IF(L23="OK",0,1)+IF(N23="OK",0,1) -> 0 | P23: =IF(RIGHT(IF(B23="","Missing SKU; ","")&IF(C23="Duplicate SKU","Duplicate SKU; ","")&IF(D23="","Missing Product Name; ","")&IF(LEFT(F23,10)="NOT MAPPED","Invalid Category ("&E23&"); ","")&IF(LEFT(J23,10)="NOT MAPPED","Invalid Size ("&I23&"); ","")&IF(L23<>"OK","Invalid Price ("&L23&"); ","")&IF(N23<>"OK","Invalid Stock ("&N23&"); ",""),2)="; ",LEFT(IF(B23="","Missing SKU; ","")&IF(C23="Duplicate SKU","Duplicate SKU; ","")&IF(D23="","Missing Product Name; ","")&IF(LEFT(F23,10)="NOT MAPPED","Invalid Category ("&E23&"); ","")&IF(LEFT(J23,10)="NOT MAPPED","Invalid Size ("&I23&"); ","")&IF(L23<>"OK","Invalid Price ("&L23&"); ","")&IF(N23<>"OK","Invalid Stock ("&N23&"); ",""),LEN(IF(B23="","Missing SKU; ","")&IF(C23="Duplicate SKU","Duplicate SKU; ","")&IF(D23="","Missing Product Name; ","")&IF(LEFT(F23,10)="NOT MAPPED","Invalid Category ("&E23&"); ","")&IF(LEFT(J23,10)="NOT MAPPED","Invalid Size ("&I23&"); ","")&IF(L23<>"OK","Invalid Price ("&L23&"); ","")&IF(N23<>"OK","Invalid Stock ("&N23&"); ",""))-2),IF(B23="","Missing SKU; ","")&IF(C23="Duplicate SKU","Duplicate SKU; ","")&IF(D23="","Missing Product Name; ","")&IF(LEFT(F23,10)="NOT MAPPED","Invalid Category ("&E23&"); ","")&IF(LEFT(J23,10)="NOT MAPPED","Invalid Size ("&I23&"); ","")&IF(L23<>"OK","Invalid Price ("&L23&"); ","")&IF(N23<>"OK","Invalid Stock ("&N23&"); ","")) | Q23: =IF(O23=0,"Ready to List",IF(O23=1,"Needs Review","Incomplete")) -> Ready to List
... A25: 28 | B25: AMC-143 | C25: =IF(B25="","",IF(COUNTIF($B$2:$B$50,B25)>1,"Duplicate SKU","")) | D25: Segiempat Katun Polos | E25: hijab | F25: =IFERROR(VLOOKUP(E25,'Category Mapping'!$A$2:$B$23,2,FALSE()),"NOT MAPPED") -> Hijab | G25: Sage Green | H25: =IF(TRIM(G25)="","",PROPER(TRIM(G25))) -> Sage Green | I25: all size | J25: =IFERROR(VLOOKUP(I25,'Size Mapping'!$A$2:$B$19,2,FALSE()),"NOT MAPPED") -> All Size | K25: 9.5 | L25: =IF(ISBLANK(K25),"Missing",IF(NOT(ISNUMBER(K25)),"Non-numeric",IF(K25<=0,"Invalid (<=0)","OK"))) -> OK | M25: 27 | N25: =IF(ISBLANK(M25),"Missing",IF(NOT(ISNUMBER(M25)),"Non-numeric",IF(M25<0,"Invalid (negative)","OK"))) -> OK | O25: =IF(B25="",1,0)+IF(C25="Duplicate SKU",1,0)+IF(D25="",1,0)+IF(LEFT(F25,10)="NOT MAPPED",1,0)+IF(LEFT(J25,10)="NOT MAPPED",1,0)+IF(L25="OK",0,1)+IF(N25="OK",0,1) -> 0 | P25: =IF(RIGHT(IF(B25="","Missing SKU; ","")&IF(C25="Duplicate SKU","Duplicate SKU; ","")&IF(D25="","Missing Product Name; ","")&IF(LEFT(F25,10)="NOT MAPPED","Invalid Category ("&E25&"); ","")&IF(LEFT(J25,10)="NOT MAPPED","Invalid Size ("&I25&"); ","")&IF(L25<>"OK","Invalid Price ("&L25&"); ","")&IF(N25<>"OK","Invalid Stock ("&N25&"); ",""),2)="; ",LEFT(IF(B25="","Missing SKU; ","")&IF(C25="Duplicate SKU","Duplicate SKU; ","")&IF(D25="","Missing Product Name; ","")&IF(LEFT(F25,10)="NOT MAPPED","Invalid Category ("&E25&"); ","")&IF(LEFT(J25,10)="NOT MAPPED","Invalid Size ("&I25&"); ","")&IF(L25<>"OK","Invalid Price ("&L25&"); ","")&IF(N25<>"OK","Invalid Stock ("&N25&"); ",""),LEN(IF(B25="","Missing SKU; ","")&IF(C25="Duplicate SKU","Duplicate SKU; ","")&IF(D25="","Missing Product Name; ","")&IF(LEFT(F25,10)="NOT MAPPED","Invalid Category ("&E25&"); ","")&IF(LEFT(J25,10)="NOT MAPPED","Invalid Size ("&I25&"); ","")&IF(L25<>"OK","Invalid Price ("&L25&"); ","")&IF(N25<>"OK","Invalid Stock ("&N25&"); ",""))-2),IF(B25="","Missing SKU; ","")&IF(C25="Duplicate SKU","Duplicate SKU; ","")&IF(D25="","Missing Product Name; ","")&IF(LEFT(F25,10)="NOT MAPPED","Invalid Category ("&E25&"); ","")&IF(LEFT(J25,10)="NOT MAPPED","Invalid Size ("&I25&"); ","")&IF(L25<>"OK","Invalid Price ("&L25&"); ","")&IF(N25<>"OK","Invalid Stock ("&N25&"); ","")) | Q25: =IF(O25=0,"Ready to List",IF(O25=1,"Needs Review","Incomplete")) -> Ready to List
A26: 29 | B26: AMC-133 | C26: =IF(B26="","",IF(COUNTIF($B$2:$B$50,B26)>1,"Duplicate SKU","")) | D26: Segiempat Voal Motif Polkadot | E26: Hijab | F26: =IFERROR(VLOOKUP(E26,'Category Mapping'!$A$2:$B$23,2,FALSE()),"NOT MAPPED") -> Hijab | G26: Blue | H26: =IF(TRIM(G26)="","",PROPER(TRIM(G26))) -> Blue | I26: Free Size | J26: =IFERROR(VLOOKUP(I26,'Size Mapping'!$A$2:$B$19,2,FALSE()),"NOT MAPPED") -> All Size | K26: TBD | L26: =IF(ISBLANK(K26),"Missing",IF(NOT(ISNUMBER(K26)),"Non-numeric",IF(K26<=0,"Invalid (<=0)","OK"))) -> Non-numeric | M26: 16 | N26: =IF(ISBLANK(M26),"Missing",IF(NOT(ISNUMBER(M26)),"Non-numeric",IF(M26<0,"Invalid (negative)","OK"))) -> OK | O26: =IF(B26="",1,0)+IF(C26="Duplicate SKU",1,0)+IF(D26="",1,0)+IF(LEFT(F26,10)="NOT MAPPED",1,0)+IF(LEFT(J26,10)="NOT MAPPED",1,0)+IF(L26="OK",0,1)+IF(N26="OK",0,1) -> 1 | P26: =IF(RIGHT(IF(B26="","Missing SKU; ","")&IF(C26="Duplicate SKU","Duplicate SKU; ","")&IF(D26="","Missing Product Name; ","")&IF(LEFT(F26,10)="NOT MAPPED","Invalid Category ("&E26&"); ","")&IF(LEFT(J26,10)="NOT MAPPED","Invalid Size ("&I26&"); ","")&IF(L26<>"OK","Invalid Price ("&L26&"); ","")&IF(N26<>"OK","Invalid Stock ("&N26&"); ",""),2)="; ",LEFT(IF(B26="","Missing SKU; ","")&IF(C26="Duplicate SKU","Duplicate SKU; ","")&IF(D26="","Missing Product Name; ","")&IF(LEFT(F26,10)="NOT MAPPED","Invalid Category ("&E26&"); ","")&IF(LEFT(J26,10)="NOT MAPPED","Invalid Size ("&I26&"); ","")&IF(L26<>"OK","Invalid Price ("&L26&"); ","")&IF(N26<>"OK","Invalid Stock ("&N26&"); ",""),LEN(IF(B26="","Missing SKU; ","")&IF(C26="Duplicate SKU","Duplicate SKU; ","")&IF(D26="","Missing Product Name; ","")&IF(LEFT(F26,10)="NOT MAPPED","Invalid Category ("&E26&"); ","")&IF(LEFT(J26,10)="NOT MAPPED","Invalid Size ("&I26&"); ","")&IF(L26<>"OK","Invalid Price ("&L26&"); ","")&IF(N26<>"OK","Invalid Stock ("&N26&"); ",""))-2),IF(B26="","Missing SKU; ","")&IF(C26="Duplicate SKU","Duplicate SKU; ","")&IF(D26="","Missing Product Name; ","")&IF(LEFT(F26,10)="NOT MAPPED","Invalid Category ("&E26&"); ","")&IF(LEFT(J26,10)="NOT MAPPED","Invalid Size ("&I26&"); ","")&IF(L26<>"OK","Invalid Price ("&L26&"); ","")&IF(N26<>"OK","Invalid Stock ("&N26&"); ","")) -> Invalid Price (Non-numeric) | Q26: =IF(O26=0,"Ready to List",IF(O26=1,"Needs Review","Incomplete")) -> Needs Review
A27: 30 | B27: AMC-101 | C27: =IF(B27="","",IF(COUNTIF($B$2:$B$50,B27)>1,"Duplicate SKU","")) | D27: Pashmina Diamond Italiano | E27: hijab | F27: =IFERROR(VLOOKUP(E27,'Category Mapping'!$A$2:$B$23,2,FALSE()),"NOT MAPPED") -> Hijab | G27: mocha brown | H27: =IF(TRIM(G27)="","",PROPER(TRIM(G27))) -> Mocha Brown | I27: all size | J27: =IFERROR(VLOOKUP(I27,'Size Mapping'!$A$2:$B$19,2,FALSE()),"NOT MAPPED") -> All Size | K27: 12.5 | L27: =IF(ISBLANK(K27),"Missing",IF(NOT(ISNUMBER(K27)),"Non-numeric",IF(K27<=0,"Invalid (<=0)","OK"))) -> OK | M27: 28 | N27: =IF(ISBLANK(M27),"Missing",IF(NOT(ISNUMBER(M27)),"Non-numeric",IF(M27<0,"Invalid (negative)","OK"))) -> OK | O27: =IF(B27="",1,0)+IF(C27="Duplicate SKU",1,0)+IF(D27="",1,0)+IF(LEFT(F27,10)="NOT MAPPED",1,0)+IF(LEFT(J27,10)="NOT MAPPED",1,0)+IF(L27="OK",0,1)+IF(N27="OK",0,1) -> 0 | P27: =IF(RIGHT(IF(B27="","Missing SKU; ","")&IF(C27="Duplicate SKU","Duplicate SKU; ","")&IF(D27="","Missing Product Name; ","")&IF(LEFT(F27,10)="NOT MAPPED","Invalid Category ("&E27&"); ","")&IF(LEFT(J27,10)="NOT MAPPED","Invalid Size ("&I27&"); ","")&IF(L27<>"OK","Invalid Price ("&L27&"); ","")&IF(N27<>"OK","Invalid Stock ("&N27&"); ",""),2)="; ",LEFT(IF(B27="","Missing SKU; ","")&IF(C27="Duplicate SKU","Duplicate SKU; ","")&IF(D27="","Missing Product Name; ","")&IF(LEFT(F27,10)="NOT MAPPED","Invalid Category ("&E27&"); ","")&IF(LEFT(J27,10)="NOT MAPPED","Invalid Size ("&I27&"); ","")&IF(L27<>"OK","Invalid Price ("&L27&"); ","")&IF(N27<>"OK","Invalid Stock ("&N27&"); ",""),LEN(IF(B27="","Missing SKU; ","")&IF(C27="Duplicate SKU","Duplicate SKU; ","")&IF(D27="","Missing Product Name; ","")&IF(LEFT(F27,10)="NOT MAPPED","Invalid Category ("&E27&"); ","")&IF(LEFT(J27,10)="NOT MAPPED","Invalid Size ("&I27&"); ","")&IF(L27<>"OK","Invalid Price ("&L27&"); ","")&IF(N27<>"OK","Invalid Stock ("&N27&"); ",""))-2),IF(B27="","Missing SKU; ","")&IF(C27="Duplicate SKU","Duplicate SKU; ","")&IF(D27="","Missing Product Name; ","")&IF(LEFT(F27,10)="NOT MAPPED","Invalid Category ("&E27&"); ","")&IF(LEFT(J27,10)="NOT MAPPED","Invalid Size ("&I27&"); ","")&IF(L27<>"OK","Invalid Price ("&L27&"); ","")&IF(N27<>"OK","Invalid Stock ("&N27&"); ","")) | Q27: =IF(O27=0,"Ready to List",IF(O27=1,"Needs Review","Incomplete")) -> Ready to List
A28: 31 | B28: AMC-135 | C28: =IF(B28="","",IF(COUNTIF($B$2:$B$50,B28)>1,"Duplicate SKU","")) | D28: Mukena Katun Jepang | E28: Prayer Set | F28: =IFERROR(VLOOKUP(E28,'Category Mapping'!$A$2:$B$23,2,FALSE()),"NOT MAPPED") -> Prayer Set | G28: Dusty Pink | H28: =IF(TRIM(G28)="","",PROPER(TRIM(G28))) -> Dusty Pink | I28: All size | J28: =IFERROR(VLOOKUP(I28,'Size Mapping'!$A$2:$B$19,2,FALSE()),"NOT MAPPED") -> All Size | K28: 28 | L28: =IF(ISBLANK(K28),"Missing",IF(NOT(ISNUMBER(K28)),"Non-numeric",IF(K28<=0,"Invalid (<=0)","OK"))) -> OK | M28: 12 | N28: =IF(ISBLANK(M28),"Missing",IF(NOT(ISNUMBER(M28)),"Non-numeric",IF(M28<0,"Invalid (negative)","OK"))) -> OK | O28: =IF(B28="",1,0)+IF(C28="Duplicate SKU",1,0)+IF(D28="",1,0)+IF(LEFT(F28,10)="NOT MAPPED",1,0)+IF(LEFT(J28,10)="NOT MAPPED",1,0)+IF(L28="OK",0,1)+IF(N28="OK",0,1) -> 0 | P28: =IF(RIGHT(IF(B28="","Missing SKU; ","")&IF(C28="Duplicate SKU","Duplicate SKU; ","")&IF(D28="","Missing Product Name; ","")&IF(LEFT(F28,10)="NOT MAPPED","Invalid Category ("&E28&"); ","")&IF(LEFT(J28,10)="NOT MAPPED","Invalid Size ("&I28&"); ","")&IF(L28<>"OK","Invalid Price ("&L28&"); ","")&IF(N28<>"OK","Invalid Stock ("&N28&"); ",""),2)="; ",LEFT(IF(B28="","Missing SKU; ","")&IF(C28="Duplicate SKU","Duplicate SKU; ","")&IF(D28="","Missing Product Name; ","")&IF(LEFT(F28,10)="NOT MAPPED","Invalid Category ("&E28&"); ","")&IF(LEFT(J28,10)="NOT MAPPED","Invalid Size ("&I28&"); ","")&IF(L28<>"OK","Invalid Price ("&L28&"); ","")&IF(N28<>"OK","Invalid Stock ("&N28&"); ",""),LEN(IF(B28="","Missing SKU; ","")&IF(C28="Duplicate SKU","Duplicate SKU; ","")&IF(D28="","Missing Product Name; ","")&IF(LEFT(F28,10)="NOT MAPPED","Invalid Category ("&E28&"); ","")&IF(LEFT(J28,10)="NOT MAPPED","Invalid Size ("&I28&"); ","")&IF(L28<>"OK","Invalid Price ("&L28&"); ","")&IF(N28<>"OK","Invalid Stock ("&N28&"); ",""))-2),IF(B28="","Missing SKU; ","")&IF(C28="Duplicate SKU","Duplicate SKU; ","")&IF(D28="","Missing Product Name; ","")&IF(LEFT(F28,10)="NOT MAPPED","Invalid Category ("&E28&"); ","")&IF(LEFT(J28,10)="NOT MAPPED","Invalid Size ("&I28&"); ","")&IF(L28<>"OK","Invalid Price ("&L28&"); ","")&IF(N28<>"OK","Invalid Stock ("&N28&"); ","")) | Q28: =IF(O28=0,"Ready to List",IF(O28=1,"Needs Review","Incomplete")) -> Ready to List
